<?xml version="1.0" ?>
<!-- =================================================================================== -->
<!-- |    This document was autogenerated by xacro from my_robot_integration.urdf.xacro | -->
<!-- |    EDITING THIS FILE BY HAND IS NOT RECOMMENDED                                 | -->
<!-- =================================================================================== -->
<!-- Name your robot here -->
<robot name="Robot_Assembly">
  <link name="base_link">
    <inertial>
      <origin rpy="0 0 0" xyz="-0.0177713241194038 -1.11022302462516E-16 0.120383167888541"/>
      <mass value="57.7200890207757"/>
      <inertia ixx="1.2991331467901" ixy="-3.51346855822824E-16" ixz="0.206009660815117" iyy="4.53263349681224" iyz="-1.51788304147971E-16" izz="5.55276261813866"/>
    </inertial>
    <visual>
      <origin rpy="0 0 0" xyz="0 0 0"/>
      <geometry>
        <mesh filename="package://Robot_Assembly/meshes/base_link.STL"/>
      </geometry>
      <material name="">
        <color rgba="0.792156862745098 0.819607843137255 0.933333333333333 1"/>
      </material>
    </visual>
    <collision>
      <origin rpy="0 0 0" xyz="0 0 0"/>
      <geometry>
        <mesh filename="package://Robot_Assembly/meshes/base_link.STL"/>
      </geometry>
    </collision>
  </link>
  <link name="rear_wheel_left">
    <inertial>
      <origin rpy="0 0 0" xyz="1.11022302462516E-16 0 -0.0418411207692297"/>
      <mass value="2.25128553479309"/>
      <inertia ixx="0.00778450520341826" ixy="-2.09752323828134E-18" ixz="1.54852475339965E-18" iyy="0.00778450520341825" iyz="6.92427076095309E-19" izz="0.0121750679482056"/>
    </inertial>
    <visual>
      <origin rpy="0 0 0" xyz="0 0 0"/>
      <geometry>
        <mesh filename="package://Robot_Assembly/meshes/rear_wheel_left.STL"/>
      </geometry>
      <material name="">
        <color rgba="0.792156862745098 0.819607843137255 0.933333333333333 1"/>
      </material>
    </visual>
    <collision>
      <origin rpy="0 0 0" xyz="0 0 0"/>
      <geometry>
        <mesh filename="package://Robot_Assembly/meshes/rear_wheel_left.STL"/>
      </geometry>
    </collision>
  </link>
  <joint name="rear_wheel_left_joint" type="continuous">
    <origin rpy="1.5707963267949 0 3.14159265358979" xyz="-0.254 0.33528 0.1016"/>
    <parent link="base_link"/>
    <child link="rear_wheel_left"/>
    <axis xyz="0 0 -1"/>
  </joint>
  <link name="rear_wheel_right">
    <inertial>
      <origin rpy="0 0 0" xyz="1.11022302462516E-16 0 -0.0418411207692296"/>
      <mass value="2.25128553479309"/>
      <inertia ixx="0.00778450520341824" ixy="-2.9356639939507E-18" ixz="2.06915499804332E-18" iyy="0.00778450520341824" iyz="-1.87290346737621E-18" izz="0.0121750679482056"/>
    </inertial>
    <visual>
      <origin rpy="0 0 0" xyz="0 0 0"/>
      <geometry>
        <mesh filename="package://Robot_Assembly/meshes/rear_wheel_right.STL"/>
      </geometry>
      <material name="">
        <color rgba="0.792156862745098 0.819607843137255 0.933333333333333 1"/>
      </material>
    </visual>
    <collision>
      <origin rpy="0 0 0" xyz="0 0 0"/>
      <geometry>
        <mesh filename="package://Robot_Assembly/meshes/rear_wheel_right.STL"/>
      </geometry>
    </collision>
  </link>
  <joint name="rear_wheel_right_joint" type="continuous">
    <origin rpy="1.5707963267949 0 0" xyz="-0.254 -0.33528 0.1016"/>
    <parent link="base_link"/>
    <child link="rear_wheel_right"/>
    <axis xyz="0 0 1"/>
  </joint>
  <link name="front_wheel_left_steering">
    <inertial>
      <origin rpy="0 0 0" xyz="-2.22044604925031E-16 -2.77555756156289E-17 -0.148810521697732"/>
      <mass value="1.36260899137696"/>
      <inertia ixx="0.00637222652336909" ixy="0.000170251792034192" ixz="-8.01290986783837E-18" iyy="0.00843770282289099" iyz="-1.46137293291981E-18" izz="0.00404982823146119"/>
    </inertial>
    <visual>
      <origin rpy="0 0 0" xyz="0 0 0"/>
      <geometry>
        <mesh filename="package://Robot_Assembly/meshes/front_wheel_left_steering.STL"/>
      </geometry>
      <material name="">
        <color rgba="0.792156862745098 0.819607843137255 0.933333333333333 1"/>
      </material>
    </visual>
    <collision>
      <origin rpy="0 0 0" xyz="0 0 0"/>
      <geometry>
        <mesh filename="package://Robot_Assembly/meshes/front_wheel_left_steering.STL"/>
      </geometry>
    </collision>
  </link>
  <joint name="front_wheel_left_steering_joint" type="continuous">
    <origin rpy="0 0 1.57079632679489" xyz="0.254 0.37592 0.30607"/>
    <parent link="base_link"/>
    <child link="front_wheel_left_steering"/>
    <axis xyz="0 0 1"/>
  </joint>
  <link name="front_wheel_left">
    <inertial>
      <origin rpy="0 0 0" xyz="0.00310902758929259 -2.1094237467878E-15 -0.0379729370400628"/>
      <mass value="1.7786506153732"/>
      <inertia ixx="0.00639043568186731" ixy="1.36807401510145E-18" ixz="-0.000377229508401982" iyy="0.00635955008173793" iyz="-3.19559257674839E-18" izz="0.0109669432168252"/>
    </inertial>
    <visual>
      <origin rpy="0 0 0" xyz="0 0 0"/>
      <geometry>
        <mesh filename="package://Robot_Assembly/meshes/front_wheel_left.STL"/>
      </geometry>
      <material name="">
        <color rgba="0.792156862745098 0.819607843137255 0.933333333333333 1"/>
      </material>
    </visual>
    <collision>
      <origin rpy="0 0 0" xyz="0 0 0"/>
      <geometry>
        <mesh filename="package://Robot_Assembly/meshes/front_wheel_left.STL"/>
      </geometry>
    </collision>
  </link>
  <joint name="front_wheel_left_joint" type="continuous">
    <origin rpy="1.5707963267949 0 1.5707963267949" xyz="0.0379729370400621 -0.00310902758929248 -0.208279999999998"/>
    <parent link="front_wheel_left_steering"/>
    <child link="front_wheel_left"/>
    <axis xyz="-0.0816017740000148 0 0.996665014174798"/>
  </joint>
  <link name="front_wheel_right_steering">
    <inertial>
      <origin rpy="0 0 0" xyz="-4.44089209850063E-16 -1.38777878078145E-17 -0.148810521697732"/>
      <mass value="1.36260899137696"/>
      <inertia ixx="0.00636320999468119" ixy="0.000101395012660662" ixz="-6.28964518379896E-18" iyy="0.0084467193515789" iyz="-3.04831628470101E-19" izz="0.00404982823146119"/>
    </inertial>
    <visual>
      <origin rpy="0 0 0" xyz="0 0 0"/>
      <geometry>
        <mesh filename="package://Robot_Assembly/meshes/front_wheel_right_steering.STL"/>
      </geometry>
      <material name="">
        <color rgba="0.792156862745098 0.819607843137255 0.933333333333333 1"/>
      </material>
    </visual>
    <collision>
      <origin rpy="0 0 0" xyz="0 0 0"/>
      <geometry>
        <mesh filename="package://Robot_Assembly/meshes/front_wheel_right_steering.STL"/>
      </geometry>
    </collision>
  </link>
  <joint name="front_wheel_right_steering_joint" type="continuous">
    <origin rpy="0 0 1.57079632679489" xyz="0.253999999999998 -0.375920000000001 0.30607"/>
    <parent link="base_link"/>
    <child link="front_wheel_right_steering"/>
    <axis xyz="0 0 1"/>
    <limit effort="0" lower="0" upper="0" velocity="0"/>
  </joint>
  <link name="front_wheel_right">
    <inertial>
      <origin rpy="0 0 0" xyz="0.00184760846713564 0 -0.0380551749825457"/>
      <mass value="1.7786506153732"/>
      <inertia ixx="0.00637045762088019" ixy="2.0172867188637E-19" ixz="-0.000224662485624304" iyy="0.00635955008173793" iyz="-7.23550391436617E-19" izz="0.0109869212778124"/>
    </inertial>
    <visual>
      <origin rpy="0 0 0" xyz="0 0 0"/>
      <geometry>
        <mesh filename="package://Robot_Assembly/meshes/front_wheel_right.STL"/>
      </geometry>
      <material name="">
        <color rgba="0.792156862745098 0.819607843137255 0.933333333333333 1"/>
      </material>
    </visual>
    <collision>
      <origin rpy="0 0 0" xyz="0 0 0"/>
      <geometry>
        <mesh filename="package://Robot_Assembly/meshes/front_wheel_right.STL"/>
      </geometry>
    </collision>
  </link>
  <joint name="front_wheel_right_joint" type="continuous">
    <origin rpy="1.57079632679489 0 -1.57079632679489" xyz="-0.0380551749825455 0.00184760846713616 -0.20828"/>
    <parent link="front_wheel_right_steering"/>
    <child link="front_wheel_right"/>
    <axis xyz="-0.0484936605547404 0 0.998823490355529"/>
  </joint>
  <link name="dummy_link">
  </link>
  <joint name="dummy_joint" type="fixed">
    <parent link="dummy_link"/>
    <child link="base_link"/>
  </joint>
  <!--Defining transmissions..-->
  <!--Steering Transmissions..-->
  <transmission name="front_wheel_left_steering_trans">
    <type>transmission_interface/SimpleTransmission</type>
    <joint name="front_wheel_left_steering_joint">
      <hardwareInterface>EffortJointInterface</hardwareInterface>
    </joint>
    <actuator name="front_wheel_left_steering_motor">
      <mechanicalReduction>50</mechanicalReduction>
    </actuator>
  </transmission>
  <transmission name="front_wheel_right_steering_trans">
    <type>transmission_interface/SimpleTransmission</type>
    <joint name="front_wheel_right_steering_joint">
      <hardwareInterface>EffortJointInterface</hardwareInterface>
    </joint>
    <actuator name="front_wheel_right_steering_motor">
      <mechanicalReduction>50</mechanicalReduction>
    </actuator>
  </transmission>
  <!--Velocity transmissions..-->
  <!--Front Wheel transmissions..-->
  <transmission name="front_wheel_left_trans">
    <type>transmission_interface/SimpleTransmission</type>
    <joint name="front_wheel_left_joint">
      <hardwareInterface>VelocityJointInterface</hardwareInterface>
    </joint>
    <actuator name="front_wheel_left_motor">
      <mechanicalReduction>50</mechanicalReduction>
    </actuator>
  </transmission>
  <transmission name="front_wheel_right_trans">
    <type>transmission_interface/SimpleTransmission</type>
    <joint name="front_wheel_right_joint">
      <hardwareInterface>VelocityJointInterface</hardwareInterface>
    </joint>
    <actuator name="front_wheel_right_motor">
      <mechanicalReduction>50</mechanicalReduction>
    </actuator>
  </transmission>
  <!--Rear Wheel transmissions..-->
  <transmission name="rear_wheel_left_trans">
    <type>transmission_interface/SimpleTransmission</type>
    <joint name="rear_wheel_left_joint">
      <hardwareInterface>VelocityJointInterface</hardwareInterface>
    </joint>
    <actuator name="rear_wheel_left_motor">
      <mechanicalReduction>50</mechanicalReduction>
    </actuator>
  </transmission>
  <transmission name="rear_wheel_right_trans">
    <type>transmission_interface/SimpleTransmission</type>
    <joint name="rear_wheel_right_joint">
      <hardwareInterface>VelocityJointInterface</hardwareInterface>
    </joint>
    <actuator name="rear_wheel_right_motor">
      <mechanicalReduction>50</mechanicalReduction>
    </actuator>
  </transmission>
  <link name="base_laser">
    <inertial>
      <origin rpy="0 0 0" xyz="-0.00029774 0.0066667 0.00013047"/>
      <mass value="0.15717"/>
      <inertia ixx="6.7885E-05" ixy="-1.3987E-07" ixz="-8.1554E-07" iyy="0.00013173" iyz="-9.0932E-08" izz="7.1972E-05"/>
    </inertial>
    <visual>
      <origin rpy="0 0 0" xyz="0 0 0"/>
      <geometry>
        <mesh filename="package://Robot_Assembly/meshes/ydlidar.dae"/>
      </geometry>
      <material name="">
        <color rgba="0.64706 0.61961 0.58824 1"/>
      </material>
    </visual>
    <collision>
      <origin rpy="0 0 0" xyz="0 0 0"/>
      <geometry>
        <mesh filename="package://Robot_Assembly/meshes/ydlidar.dae"/>
      </geometry>
    </collision>
  </link>
  <link name="laser_frame">
    <inertial>
      <origin rpy="0 0 0" xyz="-0.00036659 0.00064155 -0.00027052"/>
      <mass value="0.25482"/>
      <inertia ixx="8.9194E-05" ixy="1.8116E-07" ixz="3.6435E-08" iyy="0.00018279" iyz="2.423E-07" izz="0.00011103"/>
    </inertial>
    <!--visual>
      <origin
        xyz="0 0 0"
        rpy="0 0 0" />
      <geometry>
        <mesh
          filename="package://ydlidar_ros/meshes/ydlidar.dae" />
      </geometry>
      <material
        name="">
        <color
          rgba="0.64706 0.61961 0.58824 1" />
      </material>
    </visual-->
    <!--collision>
      <origin
        xyz="0 0 0"
        rpy="0 0 0" />
      <geometry>
        <mesh
          filename="package://ydlidar_ros/meshes/ydlidar.dae" />
      </geometry>
    </collision-->
  </link>
  <joint name="laser_joint" type="fixed">
    <origin rpy="0 0 0" xyz="0 0 0.03172"/>
    <parent link="base_laser"/>
    <child link="laser_frame"/>
    <axis xyz="0 0 0"/>
  </joint>
  <!-- <gravity>true</gravity> -->
  <!-- Gazebo has fixed set of Sensors types. Check them out here <> -->
  <sensor name="laser" type="ray">
    <!-- Add in your sensor characteristics -->
    <pose> 0 0 0 0 0 0 </pose>
    <visualise>true</visualise>
    <update_rate>40</update_rate>
    <!-- <always_on>true</always_on> -->
    <ray>
      <scan>
        <horizontal>
          <samples>720</samples>
          <resolution>1</resolution>
          <min_angle>-1.570796</min_angle>
          <max_angle>1.570796</max_angle>
        </horizontal>
      </scan>
      <range>
        <min>0.10</min>
        <max>30.0</max>
        <resolution>0.01</resolution>
      </range>
      <noise>
        <type>gaussian</type>
        <mean>0.0</mean>
        <stddev>0.01</stddev>
      </noise>
    </ray>
    <plugin filename="libgazebo_ros_laser.so" name="gazebo_ros_head_hokuyo_controller">
      <!-- Use topic name as /my_robot/scan -->
      <topicName/>
      <frameName>laser_frame</frameName>
    </plugin>
  </sensor>
  <!--  Gazebo plugin for control here is already added for you -->
  <gazebo>
    <plugin filename="libgazebo_ros_control.so" name="gazebo_ros_control">
      <robotNamespace>/Robot_Assembly</robotNamespace>
      <robotSimType>gazebo_ros_control/DefaultRobotHWSim</robotSimType>
      <legacyModeNS>true</legacyModeNS>
    </plugin>
  </gazebo>
  <!-- Create a joint between your robot and sensor -->
  <joint name="lidar_joint" type="fixed">
    <parent link="base_link"/>
    <child link="base_laser"/>
    <origin xyz="0.35 0 0.150383167888541"/>
  </joint>
</robot>
