<?xml version="1.0" encoding="utf-8"?>
<!-- This URDF was automatically created by SolidWorks to URDF Exporter! Originally created by Stephen Brawner (brawner@gmail.com) 
     Commit Version: 1.6.0-4-g7f85cfe  Build Version: 1.6.7995.38578
     For more information, please see http://wiki.ros.org/sw_urdf_exporter -->
<robot
  name="Robot_Assembly">
  <link
    name="base_link">
    <inertial>
      <origin
        xyz="-0.0177713241194038 -1.11022302462516E-16 0.120383167888541"
        rpy="0 0 0" />
      <mass
        value="57.7200890207757" />
      <inertia
        ixx="1.2991331467901"
        ixy="-3.51346855822824E-16"
        ixz="0.206009660815117"
        iyy="4.53263349681224"
        iyz="-1.51788304147971E-16"
        izz="5.55276261813866" />
    </inertial>
    <visual>
      <origin
        xyz="0 0 0"
        rpy="0 0 0" />
      <geometry>
        <mesh
          filename="package://Robot_Assembly/meshes/base_link.STL" />
      </geometry>
      <material
        name="">
        <color
          rgba="0.792156862745098 0.819607843137255 0.933333333333333 1" />
      </material>
    </visual>
    <collision>
      <origin
        xyz="0 0 0"
        rpy="0 0 0" />
      <geometry>
        <mesh
          filename="package://Robot_Assembly/meshes/base_link.STL" />
      </geometry>
    </collision>
  </link>
  <link
    name="rear_wheel_left">
    <inertial>
      <origin
        xyz="1.11022302462516E-16 0 -0.0418411207692297"
        rpy="0 0 0" />
      <mass
        value="2.25128553479309" />
      <inertia
        ixx="0.00778450520341826"
        ixy="-2.09752323828134E-18"
        ixz="1.54852475339965E-18"
        iyy="0.00778450520341825"
        iyz="6.92427076095309E-19"
        izz="0.0121750679482056" />
    </inertial>
    <visual>
      <origin
        xyz="0 0 0"
        rpy="0 0 0" />
      <geometry>
        <mesh
          filename="package://Robot_Assembly/meshes/rear_wheel_left.STL" />
      </geometry>
      <material
        name="">
        <color
          rgba="0.792156862745098 0.819607843137255 0.933333333333333 1" />
      </material>
    </visual>
    <collision>
      <origin
        xyz="0 0 0"
        rpy="0 0 0" />
      <geometry>
        <mesh
          filename="package://Robot_Assembly/meshes/rear_wheel_left.STL" />
      </geometry>
    </collision>
  </link>
  <joint
    name="rear_wheel_left_joint"
    type="continuous">
    <origin
      xyz="-0.254 0.33528 0.1016"
      rpy="1.5707963267949 0 3.14159265358979" />
    <parent
      link="base_link" />
    <child
      link="rear_wheel_left" />
    <axis
      xyz="0 0 -1" />
  </joint>
  <link
    name="rear_wheel_right">
    <inertial>
      <origin
        xyz="1.11022302462516E-16 0 -0.0418411207692296"
        rpy="0 0 0" />
      <mass
        value="2.25128553479309" />
      <inertia
        ixx="0.00778450520341824"
        ixy="-2.9356639939507E-18"
        ixz="2.06915499804332E-18"
        iyy="0.00778450520341824"
        iyz="-1.87290346737621E-18"
        izz="0.0121750679482056" />
    </inertial>
    <visual>
      <origin
        xyz="0 0 0"
        rpy="0 0 0" />
      <geometry>
        <mesh
          filename="package://Robot_Assembly/meshes/rear_wheel_right.STL" />
      </geometry>
      <material
        name="">
        <color
          rgba="0.792156862745098 0.819607843137255 0.933333333333333 1" />
      </material>
    </visual>
    <collision>
      <origin
        xyz="0 0 0"
        rpy="0 0 0" />
      <geometry>
        <mesh
          filename="package://Robot_Assembly/meshes/rear_wheel_right.STL" />
      </geometry>
    </collision>
  </link>
  <joint
    name="rear_wheel_right_joint"
    type="continuous">
    <origin
      xyz="-0.254 -0.33528 0.1016"
      rpy="1.5707963267949 0 0" />
    <parent
      link="base_link" />
    <child
      link="rear_wheel_right" />
    <axis
      xyz="0 0 1" />
  </joint>
  <link
    name="front_wheel_left_steering">
    <inertial>
      <origin
        xyz="-2.22044604925031E-16 -2.77555756156289E-17 -0.148810521697732"
        rpy="0 0 0" />
      <mass
        value="1.36260899137696" />
      <inertia
        ixx="0.00637222652336909"
        ixy="0.000170251792034192"
        ixz="-8.01290986783837E-18"
        iyy="0.00843770282289099"
        iyz="-1.46137293291981E-18"
        izz="0.00404982823146119" />
    </inertial>
    <visual>
      <origin
        xyz="0 0 0"
        rpy="0 0 0" />
      <geometry>
        <mesh
          filename="package://Robot_Assembly/meshes/front_wheel_left_steering.STL" />
      </geometry>
      <material
        name="">
        <color
          rgba="0.792156862745098 0.819607843137255 0.933333333333333 1" />
      </material>
    </visual>
    <collision>
      <origin
        xyz="0 0 0"
        rpy="0 0 0" />
      <geometry>
        <mesh
          filename="package://Robot_Assembly/meshes/front_wheel_left_steering.STL" />
      </geometry>
    </collision>
  </link>
  <joint
    name="front_wheel_left_steering_joint"
    type="revolute">
    <limit effort = "1000" lower = "-1.0" upper="1.0" velocity="2.0"/>
    <origin
      xyz="0.254 0.37592 0.30607"
      rpy="0 0 1.57079632679489" />
    <parent
      link="base_link" />
    <child
      link="front_wheel_left_steering" />
    <axis
      xyz="0 0 1" />
  </joint>
  <link
    name="front_wheel_left">
    <inertial>
      <origin
        xyz="0.00310902758929259 -2.1094237467878E-15 -0.0379729370400628"
        rpy="0 0 0" />
      <mass
        value="1.7786506153732" />
      <inertia
        ixx="0.00639043568186731"
        ixy="1.36807401510145E-18"
        ixz="-0.000377229508401982"
        iyy="0.00635955008173793"
        iyz="-3.19559257674839E-18"
        izz="0.0109669432168252" />
    </inertial>
    <visual>
      <origin
        xyz="0 0 0"
        rpy="0 0 0" />
      <geometry>
        <mesh
          filename="package://Robot_Assembly/meshes/front_wheel_left.STL" />
      </geometry>
      <material
        name="">
        <color
          rgba="0.792156862745098 0.819607843137255 0.933333333333333 1" />
      </material>
    </visual>
    <collision>
      <origin
        xyz="0 0 0"
        rpy="0 0 0" />
      <geometry>
        <mesh
          filename="package://Robot_Assembly/meshes/front_wheel_left.STL" />
      </geometry>
    </collision>
  </link>
  <joint
    name="front_wheel_left_joint"
    type="continuous">
    <origin
      xyz="0.0379729370400621 -0.00310902758929248 -0.208279999999998"
      rpy="1.5707963267949 0 1.5707963267949" />
    <parent
      link="front_wheel_left_steering" />
    <child
      link="front_wheel_left" />
    <axis
      xyz="-0.0816017740000148 0 0.996665014174798" />
  </joint>
  <link
    name="front_wheel_right_steering">
    <inertial>
      <origin
        xyz="-4.44089209850063E-16 -1.38777878078145E-17 -0.148810521697732"
        rpy="0 0 0" />
      <mass
        value="1.36260899137696" />
      <inertia
        ixx="0.00636320999468119"
        ixy="0.000101395012660662"
        ixz="-6.28964518379896E-18"
        iyy="0.0084467193515789"
        iyz="-3.04831628470101E-19"
        izz="0.00404982823146119" />
    </inertial>
    <visual>
      <origin
        xyz="0 0 0"
        rpy="0 0 0" />
      <geometry>
        <mesh
          filename="package://Robot_Assembly/meshes/front_wheel_right_steering.STL" />
      </geometry>
      <material
        name="">
        <color
          rgba="0.792156862745098 0.819607843137255 0.933333333333333 1" />
      </material>
    </visual>
    <collision>
      <origin
        xyz="0 0 0"
        rpy="0 0 0" />
      <geometry>
        <mesh
          filename="package://Robot_Assembly/meshes/front_wheel_right_steering.STL" />
      </geometry>
    </collision>
  </link>
  <joint
    name="front_wheel_right_steering_joint"
    type="revolute">
    <limit  effort = "1000"  lower = "-1.0" upper="1.0" velocity="2.0"/>
    <origin
      xyz="0.253999999999998 -0.375920000000001 0.30607"
      rpy="0 0 1.57079632679489" />
    <parent
      link="base_link" />
    <child
      link="front_wheel_right_steering" />
    <axis
      xyz="0 0 1" />
    <limit
      lower="0"
      upper="0"
      effort="0"
      velocity="0" />
  </joint>
  <link
    name="front_wheel_right">
    <inertial>
      <origin
        xyz="0.00184760846713564 0 -0.0380551749825457"
        rpy="0 0 0" />
      <mass
        value="1.7786506153732" />
      <inertia
        ixx="0.00637045762088019"
        ixy="2.0172867188637E-19"
        ixz="-0.000224662485624304"
        iyy="0.00635955008173793"
        iyz="-7.23550391436617E-19"
        izz="0.0109869212778124" />
    </inertial>
    <visual>
      <origin
        xyz="0 0 0"
        rpy="0 0 0" />
      <geometry>
        <mesh
          filename="package://Robot_Assembly/meshes/front_wheel_right.STL" />
      </geometry>
      <material
        name="">
        <color
          rgba="0.792156862745098 0.819607843137255 0.933333333333333 1" />
      </material>
    </visual>
    <collision>
      <origin
        xyz="0 0 0"
        rpy="0 0 0" />
      <geometry>
        <mesh
          filename="package://Robot_Assembly/meshes/front_wheel_right.STL" />
      </geometry>
    </collision>
  </link>
  <joint
    name="front_wheel_right_joint"
    type="continuous">
    <origin
      xyz="-0.0380551749825455 0.00184760846713616 -0.20828"
      rpy="1.57079632679489 0 -1.57079632679489" />
    <parent
      link="front_wheel_right_steering" />
    <child
      link="front_wheel_right" />
    <axis
      xyz="-0.0484936605547404 0 0.998823490355529" />
  </joint>
  <link name="base_lidar_link">
       <visual>
         <geometry>
           <cylinder length="0.25" radius="0.05"/>
         </geometry>
         <origin rpy="0 0 0" xyz="0.35 0 0.250383167888541"/>
       </visual>
  </link>
  <joint name="base_lidar_link_joint" type="fixed">
      <parent
        link="base_link" />
      <child
        link="base_lidar_link"/>
  </joint>
  <!--Defining transmissions..-->
  <!--Steering Transmissions..-->
  <transmission name="front_wheel_left_steering_trans">
   <type>transmission_interface/SimpleTransmission</type>
   <joint name="front_wheel_left_steering_joint">
   <hardwareInterface>hardware_interface/EffortJointInterface</hardwareInterface>
   </joint>
   <actuator name="front_wheel_left_steering_motor">
   <mechanicalReduction>50</mechanicalReduction>
   </actuator>
  </transmission>
  <transmission name="front_wheel_right_steering_trans">
   <type>transmission_interface/SimpleTransmission</type>
   <joint name="front_wheel_right_steering_joint">
   <hardwareInterface>hardware_interface/EffortJointInterface</hardwareInterface>
   </joint>
   <actuator name="front_wheel_right_steering_motor">
   <mechanicalReduction>50</mechanicalReduction>
   </actuator>
  </transmission>
  <!--Velocity transmissions..-->
  <!--Front Wheel transmissions..-->
  <transmission name="front_wheel_left_trans">
   <type>transmission_interface/SimpleTransmission</type>
   <joint name="front_wheel_left_joint">
   <hardwareInterface>hardware_interface/VelocityJointInterface</hardwareInterface>
   </joint>
   <actuator name="front_wheel_left_motor">
   <mechanicalReduction>50</mechanicalReduction>
   </actuator>
  </transmission>
  <transmission name="front_wheel_right_trans">
   <type>transmission_interface/SimpleTransmission</type>
   <joint name="front_wheel_right_joint">
   <hardwareInterface>hardware_interface/VelocityJointInterface</hardwareInterface>
   </joint>
   <actuator name="front_wheel_right_motor">
   <mechanicalReduction>50</mechanicalReduction>
   </actuator>
  </transmission>
  <!--Rear Wheel transmissions..-->
  <transmission name="rear_wheel_left_trans">
   <type>transmission_interface/SimpleTransmission</type>
   <joint name="rear_wheel_left_joint">
   <hardwareInterface>hardware_interface/VelocityJointInterface</hardwareInterface>
   </joint>
   <actuator name="rear_wheel_left_motor">
   <mechanicalReduction>50</mechanicalReduction>
   </actuator>
  </transmission>
  <transmission name="rear_wheel_right_trans">
   <type>transmission_interface/SimpleTransmission</type>
   <joint name="rear_wheel_right_joint">
   <hardwareInterface>hardware_interface/VelocityJointInterface</hardwareInterface>
   </joint>
   <actuator name="rear_wheel_right_motor">
   <mechanicalReduction>50</mechanicalReduction>
   </actuator>
  </transmission>
</robot>